Workbook
Name bonito: '[1]CENTRO DE CUSTO'!#REF!
Name bonito: '[2]CENTRO DE CUSTO'!#REF!
Name bonito: 'CENTRO DE CUSTO'!#REF!
Name bonito_1: #REF!
Name bonito_1: #REF!
Name bonito_10: '[1]CENTRO DE CUSTO'!#REF!
Name bonito_10: '[2]CENTRO DE CUSTO'!#REF!
Name bonito_10: 'CENTRO DE CUSTO'!#REF!
Name bonito_10_1: #REF!
Name bonito_10_1: #REF!
Name bonito_11: '[1]CENTRO DE CUSTO'!#REF!
Name bonito_11: '[2]CENTRO DE CUSTO'!#REF!
Name bonito_11: 'CENTRO DE CUSTO'!#REF!
Name bonito_11_1: #REF!
Name bonito_11_1: #REF!
Name bonito_12: '[1]CENTRO DE CUSTO'!#REF!
Name bonito_12: '[2]CENTRO DE CUSTO'!#REF!
Name bonito_12: 'CENTRO DE CUSTO'!#REF!
Name bonito_12_1: #REF!
Name bonito_12_1: #REF!
Name bonito_13: '[1]CENTRO DE CUSTO'!#REF!
Name bonito_13: '[2]CENTRO DE CUSTO'!#REF!
Name bonito_13: 'CENTRO DE CUSTO'!#REF!
Name bonito_13_1: #REF!
Name bonito_13_1: #REF!
Name bonito_14: '[1]CENTRO DE CUSTO'!#REF!
Name bonito_14: '[2]CENTRO DE CUSTO'!#REF!
Name bonito_14: 'CENTRO DE CUSTO'!#REF!
Name bonito_14_1: #REF!
Name bonito_14_1: #REF!
Name bonito_15: '[1]CENTRO DE CUSTO'!#REF!
Name bonito_15: '[2]CENTRO DE CUSTO'!#REF!
Name bonito_15: 'CENTRO DE CUSTO'!#REF!
Name bonito_15_1: #REF!
Name bonito_15_1: #REF!
Name bonito_16: '[1]CENTRO DE CUSTO'!#REF!
Name bonito_16: '[2]CENTRO DE CUSTO'!#REF!
Name bonito_16: 'CENTRO DE CUSTO'!#REF!
Name bonito_16_1: #REF!
Name bonito_16_1: #REF!
Name bonito_17: '[1]CENTRO DE CUSTO'!#REF!
Name bonito_17: '[2]CENTRO DE CUSTO'!#REF!
Name bonito_17: 'CENTRO DE CUSTO'!#REF!
Name bonito_17_1: #REF!
Name bonito_17_1: #REF!
Name bonito_18: '[1]CENTRO DE CUSTO'!#REF!
Name bonito_18: '[2]CENTRO DE CUSTO'!#REF!
Name bonito_18: 'CENTRO DE CUSTO'!#REF!
Name bonito_18_1: #REF!
Name bonito_18_1: #REF!
Name bonito_19: '[1]CENTRO DE CUSTO'!#REF!
Name bonito_19: '[2]CENTRO DE CUSTO'!#REF!
Name bonito_19: 'CENTRO DE CUSTO'!#REF!
Name bonito_19_1: #REF!
Name bonito_19_1: #REF!
Name bonito_3: '[1]CENTRO DE CUSTO'!#REF!
Name bonito_3: '[2]CENTRO DE CUSTO'!#REF!
Name bonito_3: 'CENTRO DE CUSTO'!#REF!
Name bonito_3_1: #REF!
Name bonito_3_1: #REF!

Sheet Marcopolo PESO ABS
B3: Cálculo para Peso de Peças Plásticas Conforme Composição Química
B6: Espessura | C6: Largura | D6: Comprimento | E6: Tipo | F6: PESO PEÇA
B7: 4 | C7: 15 | D7: 550 | E7: ABS | F7: =IF(E7="ABS",((B7*C7*D7*C63)/1000000),(IF(E7="PEAD",((B7*C7*D7*C64)/1000000),(IF(E7="PP",((B7*C7*D7*C65)/1000000),1)))*1)) -> 0.03498
F8: PESO DA PEÇA +30%
F9: =F7+F7*30% -> 0.045474
Z12: 0.6
Z13: 0.232
Z15: 0.16
Z16: =SUM(Z12:Z15) -> 0.992
B63: ABS | C63: 1.06
B64: PEAD | C64: 0.96
B65: PP | C65: 0.95
B67: ESPESSURA | C67: 4
C68: 5.75
C69: 3
C70: 6.5
C71: 2
C72: 1.5
C73: 5

Sheet ORÇAMENTO INSERTOS
A1: FICHA DE ORÇAMENTO
A2: DESCRIÇÃO DA PEÇA: | F2: CÓDIGO / DESENHO: | J2: LOTE ECONÔMICO: | K2: 100
A3: ESTRUTURA DE PRODUTO
A4: CÓD. MATERIAL | B4: DESCRIÇÃO DOS COMPONENTES | E4: QUANTIDADE | F4: UN | G4: PREÇO ( R$ ) | I4: OBSERVAÇÃO | K4: TOTAL R$
A6: 109299000 | B6: CHAPA DE ACO 1,90 x 1000 x 3000mm - NBR7008 ZEE GRAU 1 Z100 | E6: 0.16 | F6: kg | G6: 7.31 | K6: =E6*G6 -> 1.1696
A7: 1064003000 | B7: CHAPA DE ALUMINIO 1,50 X 1000 X 2000 mm - LIGA 1200 - H14 | F7: kg | G7: 28.75 | K7: =E7*G7 -> 0
A8: 107679000 | B8: CHAPA DE ACO 1,55X1000X2680 - NBR 7008 ZEE - GRAU 2 - Z100 | F8: kg | G8: 6.76 | K8: =E8*G8 -> 0
A9: 107676000 | B9: CHAPA DE ACO 1,20X1500X1795 - ST 05 Z/NBR 7008 ZEE GRAU 2,+Z | F9: kg | G9: 8.54 | K9: =E9*G9 -> 0
A10: 106546000 | B10: CHAPA DE ACO 1,55mm 1200 x 3000mm NBR 7008 ZEE GR1 (Z100) | F10: kg | G10: 4.2525 | K10: =E10*G10 -> 0
A11: 100755000 | B11: =IF(A11="","",VLOOKUP(A11,'[3]Dados MSQUERY Texto 18.02.2014'!$A$1:$D$65533,2,FALSE)) -> CHAPA DE ACO 3,00 mm FQ 1200 x 3000 - SAE 1008 DEC | F11: kg | G11: 6.87 | K11: =E11*G11 -> 0
A12: 100106000 | B12: =IF(A12="","",VLOOKUP(A12,'[3]Dados MSQUERY Texto 18.02.2014'!$A$1:$D$65533,2,FALSE)) -> CHAPA DE ACO 1,50mm FF 1200 x 3000 NBR5915 EM | F12: kg | G12: 5.91 | K12: =E12*G12 -> 0
A13: 109796000 | B13: =IF(A13="","",VLOOKUP(A13,'[3]Dados MSQUERY Texto 18.02.2014'!$A$1:$D$65533,2,FALSE)) -> CHAPA DE ACO 1,90mm FF 1500 x 3000 | F13: kg | G13: 5.0438 | K13: =E13*G13 -> 0
A14: 106039000 | B14: =IF(A14="","",VLOOKUP(A14,'[3]Dados MSQUERY Texto 18.02.2014'!$A$1:$D$65533,2,FALSE)) -> CHAPA DE ACO 4,25mm FQ 1200 x 3000 - NBR 6656 LNE - 38 | F14: kg | G14: 5.849 | K14: =E14*G14 -> 0
A15: 103085000 | B15: =IF(A15="","",VLOOKUP(A15,'[3]Dados MSQUERY Texto 18.02.2014'!$A$1:$D$65533,2,FALSE)) -> CHAPA DE ACO 6,35mm FQ 1200 x 3000 - SAE 1010/20 | F15: kg | G15: 4.22 | K15: =E15*G15 -> 0
A16: 109389000 | B16: CHAPA DE ACO 1,00 x 1500 x 2700mm GI EN10346 DX56D Z140-M-C- | F16: kg | G16: 6.87 | K16: =E16*G16 -> 0
A17: 103209000 | B17: =IF(A17="","",VLOOKUP(A17,'[3]Dados MSQUERY Texto 18.02.2014'!$A$1:$D$65533,2,FALSE)) -> CHAPA DE ACO 1,20mm FF 1200 x 3000 EM | F17: kg | G17: 5.1084 | K17: =E17*G17 -> 0
A18: 106475000 | B18: MANTA DE ISOLAMENTO | F18: M² | G18: 39.283 | K18: =E18*G18 -> 0
A19: 100634000 | B19: =IF(A19="","",VLOOKUP(A19,'[3]Dados MSQUERY Texto 18.02.2014'!$A$1:$D$65533,2,FALSE)) -> PRIMER PRETO IMERSAO BASE D. AGUA | F19: L | G19: 23.53 | K19: =E19*G19 -> 0
A20: 100106000 | B20: CHAPA DE ACO 4,75mm FQD 1200 x 3000 - SAE 1006 DEC | F20: kg | G20: 5.8373 | K20: =E20*G20 -> 0
A21: 107670000 | B21: CHAPA DE AÇO 6,35 x 1200 x 2000mm - NBR 6656 LNE-38 DECOL | F21: kg | G21: 5.91 | K21: =E21*G21 -> 0
A22: SOMATÓRIO DOS VALORES REFERENTES A MATÉRIA-PRIMA................................................ | K22: =SUM(K6:K19) -> 1.1696
A24: OPERAÇÕES EXTERNAS (TERCEIROS)
A25: CÓDIGO | B25: DESCRIÇÃO | C25: QUANTIDADE | D25: UN | E25: FORNECEDOR SERVIÇO | H25: OBSERVAÇÃO | J25: PREÇO UNIT. (R$) | K25: R$
K27: =J27*C27 -> 0
K28: =J28*C28 -> 0
K29: =J29*C29 -> 0
A30: SOMATÓRIO DOS VALORES REFERENTES A OPERAÇÃO EXTERNA (TERCEIROS).............................................. | K30: =SUM(K27:K29) -> 0
A32: PROCESSO DE FABRICAÇÃO | M32: 1
A33: Nº OPERAÇÃO | B33: DESCRIÇÃO DA OPERAÇÃO | C33: CENTRO CUSTO | D33: GRUPO MÁQUINA | E33: DESCRIÇÃO GRUPO MÁQUINA | G33: SET-UP (MINUTOS) | H33: TEMPO OPERAÇÃO (MINUTOS) | I33: Nº DE HOMENS | J33: R$ (SET-UP) | K33: R$ (TEMPO OPERAÇÃO) | M33: 2
L34: =I35*H35 -> 0.3 | M34: 3
A35: 10 | B35: CORTAR CHAPA EM TIRA | C35: 359 | D35: 301-002 | E35: =IF(D35="","",VLOOKUP(D35,'GRUPO MÁQUINA 2025'!A2:B400,2,0)) -> GUILHOTINA MECANICA NEWTON | G35: 4.5 | H35: 0.1 | I35: 3 | J35: =IF(C35<>"",VLOOKUP(C35,'CENTRO DE CUSTO'!$A$3:$C$536,3,0)*G35/$K$2/60,"") -> 0.105 | K35: =IF(C35<>"",VLOOKUP(C35,'CENTRO DE CUSTO'!$A$3:$C$536,3,0)*H35/60*I35,"") -> 0.7 | L35: =I36*H36 -> 0.2 | M35: 4
A36: 20 | B36: CORTAR CHAPA EM BLANK | C36: 359 | D36: 301-002 | E36: =IF(D36="","",VLOOKUP(D36,'GRUPO MÁQUINA 2025'!A3:B401,2,0)) -> GUILHOTINA MECANICA NEWTON | G36: 4.5 | H36: 0.1 | I36: 2 | J36: =IF(C36<>"",VLOOKUP(C36,'CENTRO DE CUSTO'!$A$3:$C$536,3,0)*G36/$K$2/60,"") -> 0.105 | K36: =IF(C36<>"",VLOOKUP(C36,'CENTRO DE CUSTO'!$A$3:$C$536,3,0)*H36/60*I36,"") -> 0.46666667 | L36: =I37*H37 -> 0 | M36: 5
A37: 30 | E37: =IF(D37="","",VLOOKUP(D37,'GRUPO MÁQUINA 2025'!A4:B402,2,0)) | J37: =IF(C37<>"",VLOOKUP(C37,'CENTRO DE CUSTO'!$A$3:$C$536,3,0)*G37/$K$2/60,"") | K37: =IF(C37<>"",VLOOKUP(C37,'CENTRO DE CUSTO'!$A$3:$C$536,3,0)*H37/60*I37,"") | L37: =I38*H38 -> 0 | M37: 6
A38: 40 | B38: CORTAR EM LASER | C38: 370 | D38: 348-004 | E38: =IF(D38="","",VLOOKUP(D38,'GRUPO MÁQUINA 2025'!A5:B403,2,0)) -> MAQUINA CORTE LASER 2D GWEIKE | I38: 1 | J38: =IF(C38<>"",VLOOKUP(C38,'CENTRO DE CUSTO'!$A$3:$C$536,3,0)*G38/$K$2/60,"") -> 0 | K38: =IF(C38<>"",VLOOKUP(C38,'CENTRO DE CUSTO'!$A$3:$C$536,3,0)*H38/60*I38,"") -> 0 | L38: =I39*H39 -> 0 | M38: 7
A39: 50 | B39: DOBRAR PECA | C39: 359 | D39: 303-003 | E39: =IF(D39="","",VLOOKUP(D39,'GRUPO MÁQUINA 2025'!A6:B404,2,0)) -> DOBRADEIRA CNC 160 TN - YAWEI | I39: 1 | J39: =IF(C39<>"",VLOOKUP(C39,'CENTRO DE CUSTO'!$A$3:$C$536,3,0)*G39/$K$2/60,"") -> 0 | K39: =IF(C39<>"",VLOOKUP(C39,'CENTRO DE CUSTO'!$A$3:$C$536,3,0)*H39/60*I39,"") -> 0 | L39: =I40*H40 -> 0 | M39: 8
A40: 60 | E40: =IF(D40="","",VLOOKUP(D40,'GRUPO MÁQUINA 2025'!A7:B405,2,0)) | J40: =IF(C40<>"",VLOOKUP(C40,'CENTRO DE CUSTO'!$A$3:$C$536,3,0)*G40/$K$2/60,"") | K40: =IF(C40<>"",VLOOKUP(C40,'CENTRO DE CUSTO'!$A$3:$C$536,3,0)*H40/60*I40,"") | L40: =I41*H41 -> 0
A41: 70 | B41: PINTAR PECA | C41: 345 | D41: 350-001 | E41: =IF(D41="","",VLOOKUP(D41,'GRUPO MÁQUINA 2025'!A8:B406,2,0)) -> CABINE DE PINTURA DE PECAS | I41: 1 | J41: =IF(C41<>"",VLOOKUP(C41,'CENTRO DE CUSTO'!$A$3:$C$536,3,0)*G41/$K$2/60,"") -> 0 | K41: =IF(C41<>"",VLOOKUP(C41,'CENTRO DE CUSTO'!$A$3:$C$536,3,0)*H41/60*I41,"") -> 0 | L41: =I42*H42 -> 0
A42: 80 | B42: ESTAMPAR | C42: 360 | D42: 336-001 | E42: =IF(D42="","",VLOOKUP(D42,'GRUPO MÁQUINA 2025'!A9:B407,2,0)) -> PRENSA EXC. GUTMANN 250 T (A) | I42: 1 | J42: =IF(C42<>"",VLOOKUP(C42,'CENTRO DE CUSTO'!$A$3:$C$536,3,0)*G42/$K$2/60,"") -> 0 | K42: =IF(C42<>"",VLOOKUP(C42,'CENTRO DE CUSTO'!$A$3:$C$536,3,0)*H42/60*I42,"") -> 0 | L42: =I43*H43 -> 0
A43: 90 | B43: SOLDAR PINOS | C43: 367 | D43: 305-008 | E43: =IF(D43="","",VLOOKUP(D43,'GRUPO MÁQUINA 2025'!A10:B408,2,0)) -> EQUIPAMENTO SOLDA MIG | I43: 1 | J43: =IF(C43<>"",VLOOKUP(C43,'CENTRO DE CUSTO'!$A$3:$C$536,3,0)*G43/$K$2/60,"") -> 0 | K43: =IF(C43<>"",VLOOKUP(C43,'CENTRO DE CUSTO'!$A$3:$C$536,3,0)*H43/60*I43,"") -> 0 | L43: =I44*H44 -> 0
A44: 100 | E44: =IF(D44="","",VLOOKUP(D44,'GRUPO MÁQUINA 2025'!A11:B409,2,0)) | J44: =IF(C44<>"",VLOOKUP(C44,'CENTRO DE CUSTO'!$A$3:$C$536,3,0)*G44/$K$2/60,"") | K44: =IF(C44<>"",VLOOKUP(C44,'CENTRO DE CUSTO'!$A$3:$C$536,3,0)*H44/60*I44,"") | L44: =I45*H45 -> 0
...

Sheet ORÇAMENTO MOLDAGEM
A4: Cor | B4: Espessura | C4: Tamanho do blank (mm) | D4: Largura (matéria-prima) | E4: Comprimento (matéria-prima) | F4: Largura (processo) | G4: Comprimento (processo) | H4: Espessura | I4: Densidade | J4: Pçs/ chapa | K4: Perímetro (m) | L4: Preparação Moldar | M4: Tempo moldar (min) | N4: Tempo destacar (min) | O4: Tempo recortar (min) | P4: Tempo acabamento (min)
N5: 0.25 | O5: 0.5 | P5: 0.9
A6: ECO1 | B6: 4 | C6: 443 x 320 | D6: =LEFT(C6,4)/1000 -> 0.443 | E6: =RIGHT(C6,4)/1000 -> 0.32 | F6: =(LEFT(C6,4)/1000) -> 0.443 | G6: =(RIGHT(C6,4)/1000) -> 0.32 | H6: =B6/1000 -> 0.004 | I6: 1060 | J6: 1 | K6: =((2*F6)+(2*G6)) -> 1.526 | L6: =IFERROR(0.1*M6,"") -> 0.575 | M6: =IFERROR(5.75/J6,"") -> 5.75 | N6: =IFERROR((K6*$N$5),"") -> 0.3815 | O6: =IFERROR((K6*$O$5),"") -> 0.763 | P6: =IFERROR((K6*$P$5),"") -> 1.3734
A7: BRANCO GEADA | B7: 6 | C7: 405 X 406 | D7: =LEFT(C7,4)/1000 -> 0.405 | E7: =RIGHT(C7,4)/1000 -> 0.406 | F7: =(LEFT(C7,4)/1000) -> 0.405 | G7: =(RIGHT(C7,4)/1000) -> 0.406 | H7: =B7/1000 -> 0.006 | I7: 1060 | J7: =IF((ROUNDDOWN((2.7/E7),0)*ROUNDDOWN((1.7/D7),0))>(ROUNDDOWN((1.7/E7),0)*ROUNDDOWN((2.7/D7),0)),(ROUNDDOWN((2.7/E7),0)*ROUNDDOWN((1.7/D7),0)),(ROUNDDOWN((1.7/E7),0)*ROUNDDOWN((2.7/D7),0))) -> 24 | K7: =((2*F7)+(2*G7)) -> 1.622 | L7: =IFERROR(0.1*M7,"") -> 0.023958333 | M7: =IFERROR(5.75/J7,"") -> 0.23958333 | N7: =IFERROR((K7*$N$5),"") -> 0.4055 | O7: =IFERROR((K7*$O$5),"") -> 0.811 | P7: =IFERROR((K7*$P$5),"") -> 1.4598
A9: FICHA DE ORÇAMENTO
A10: DESCRIÇÃO DA PEÇA: | F10: CÓDIGO / DESENHO: | H10: - | J10: LOTE ECONÔMICO: | K10: 100
A11: ESTRUTURA DE PRODUTO
A12: CÓD. MATERIAL | B12: DESCRIÇÃO DOS COMPONENTES | E12: QUANTIDADE | F12: UN | G12: PREÇO ( R$ ) | I12: OBSERVAÇÃO | K12: TOTAL R$
F14: KG | K14: =E14*G14 -> 0
A15: 101136000 | B15: =IF(A15="","",VLOOKUP(A15,'[2]Dados MSQUERY Texto 18.02.2014'!$A$1:$D$65532,2,FALSE)) -> ADESIVO ESTRUTURAL METACRILATO ARALDITE | F15: KG | G15: 128.51 | K15: =E15*G15 -> 0
A16: 101137000 | B16: =IF(A16="","",VLOOKUP(A16,'[2]Dados MSQUERY Texto 18.02.2014'!$A$1:$D$65532,2,FALSE)) -> ATIVADOR P/ ADESIVO ESTRUTURAL METACRILATO | F16: KG | G16: 128.51 | K16: =E16*G16 -> 0
B17: =IF(A17="","",VLOOKUP(A17,'[2]Dados MSQUERY Texto 18.02.2014'!$A$1:$D$65532,2,FALSE)) | F17: =IF(B17="","",VLOOKUP(A17,'[2]Dados MSQUERY Texto 18.02.2014'!$A$1:$D$65532,4,FALSE)) | K17: =E17*G17 -> 0
A18: SOMATÓRIO DOS VALORES REFERENTES A MATÉRIA-PRIMA................................................ | K18: =SUM(K14:K17) -> 0
A20: OPERAÇÕES EXTERNAS (TERCEIROS)
A21: CÓDIGO | B21: DESCRIÇÃO | C21: QUANTIDADE | D21: UN | E21: FORNECEDOR SERVIÇO | H21: OBSERVAÇÃO | J21: PREÇO UNIT. (R$) | K21: R$
K23: =J23*C23 -> 0
K24: =J24*C24 -> 0
K25: =J25*C25 -> 0
A26: SOMATÓRIO DOS VALORES REFERENTES A OPERAÇÃO EXTERNA (TERCEIROS).............................................. | K26: =SUM(K23:K25) -> 0
A28: PROCESSO DE FABRICAÇÃO
A29: Nº OPERAÇÃO | B29: DESCRIÇÃO DA OPERAÇÃO | C29: CENTRO CUSTO | D29: GRUPO MÁQUINA | E29: DESCRIÇÃO GRUPO MÁQUINA | G29: SET-UP (MINUTOS) | H29: TEMPO OPERAÇÃO (MINUTOS) | I29: Nº DE HOMENS | J29: R$ (SET-UP) | K29: R$ (TEMPO OPERAÇÃO) | M29: 1
M30: 2
A31: 10 | B31: MOLDAR PEÇA | C31: 368 | D31: 343A | E31: =IF(D31="","",VLOOKUP(D31,'[2]GRUPO MÁQUINA 2025'!A2:B399,2,0)) -> MÁQ. TERMO FORMAGEM (A) MARCOPOLO | G31: =L7 -> 0.023958333 | H31: =M7 -> 0.23958333 | I31: 1 | J31: =IF(C31<>"",VLOOKUP(C31,'[2]CENTRO DE CUSTO'!$A$3:$C$536,3,0)*G31/$K$10/60,"") -> 0.00100625 | K31: =IF(C31<>"",VLOOKUP(C31,'CENTRO DE CUSTO'!$A$3:$C$536,3,0)*H31/60*I31,"") -> 1.00625 | L31: =I31*H31 -> 0.23958333 | M31: 3
A32: 20 | B32: DESTACAR PEÇA | C32: 369 | D32: 339-014 | E32: =IF(D32="","",VLOOKUP(D32,'[2]GRUPO MÁQUINA 2025'!A3:B400,2,0)) -> DESTACAR PEÇA 1 | H32: =N7 -> 0.4055 | I32: 1 | J32: =IF(C32<>"",VLOOKUP(C32,'[2]CENTRO DE CUSTO'!$A$3:$C$536,3,0)*G32/$K$10/60,"") -> 0 | K32: =IF(C32<>"",VLOOKUP(C32,'CENTRO DE CUSTO'!$A$3:$C$536,3,0)*H32/60*I32,"") -> 0.709625 | L32: =I32*H32 -> 0.4055 | M32: 4
A33: 30 | B33: RECORTAR PEÇA | C33: 369 | D33: 339-015 | E33: =IF(D33="","",VLOOKUP(D33,'[2]GRUPO MÁQUINA 2025'!A4:B401,2,0)) -> CORTE TUPIA | H33: =O7 -> 0.811 | I33: 1 | J33: =IF(C33<>"",VLOOKUP(C33,'[2]CENTRO DE CUSTO'!$A$3:$C$536,3,0)*G33/$K$10/60,"") -> 0 | K33: =IF(C33<>"",VLOOKUP(C33,'CENTRO DE CUSTO'!$A$3:$C$536,3,0)*H33/60*I33,"") -> 1.41925 | L33: =I33*H33 -> 0.811 | M33: 5
A34: 40 | B34: DAR ACABAMENTO | C34: 369 | D34: 339-013 | E34: =IF(D34="","",VLOOKUP(D34,'[2]GRUPO MÁQUINA 2025'!A5:B402,2,0)) -> LIXADEIRA 1 | H34: =P7 -> 1.4598 | I34: 1 | J34: =IF(C34<>"",VLOOKUP(C34,'[2]CENTRO DE CUSTO'!$A$3:$C$536,3,0)*G34/$K$10/60,"") -> 0 | K34: =IF(C34<>"",VLOOKUP(C34,'CENTRO DE CUSTO'!$A$3:$C$536,3,0)*H34/60*I34,"") -> 2.55465 | L34: =I34*H34 -> 1.4598 | M34: 6
A35: 50 | B35: MONTAR CONJUNTO | C35: 369 | D35: 351-003 | E35: =IF(D35="","",VLOOKUP(D35,'[2]GRUPO MÁQUINA 2025'!A6:B403,2,0)) -> MON/COL 1 - MARCOPOLO | H35: 8 | I35: 1 | J35: =IF(C35<>"",VLOOKUP(C35,'[2]CENTRO DE CUSTO'!$A$3:$C$536,3,0)*G35/$K$10/60,"") -> 0 | K35: =IF(C35<>"",VLOOKUP(C35,'CENTRO DE CUSTO'!$A$3:$C$536,3,0)*H35/60*I35,"") -> 14 | L35: =I35*H35 -> 8 | M35: 7
A36: 60 | E36: =IF(D36="","",VLOOKUP(D36,'[2]GRUPO MÁQUINA 2025'!A7:B404,2,0)) | J36: =IF(C36<>"",VLOOKUP(C36,'[2]CENTRO DE CUSTO'!$A$3:$C$536,3,0)*G36/$K$10/60,"") | K36: =IF(C36<>"",VLOOKUP(C36,'CENTRO DE CUSTO'!$A$3:$C$536,3,0)*H36/60*I36,"") | L36: =I36*H36 -> 0 | M36: 8
A37: 70 | E37: =IF(D37="","",VLOOKUP(D37,'[2]GRUPO MÁQUINA 2025'!A8:B405,2,0)) | J37: =IF(C37<>"",VLOOKUP(C37,'[2]CENTRO DE CUSTO'!$A$3:$C$536,3,0)*G37/$K$10/60,"") | K37: =IF(C37<>"",VLOOKUP(C37,'CENTRO DE CUSTO'!$A$3:$C$536,3,0)*H37/60*I37,"") | L37: =I37*H37 -> 0
A38: 80 | E38: =IF(D38="","",VLOOKUP(D38,'[2]GRUPO MÁQUINA 2025'!A9:B406,2,0)) | J38: =IF(C38<>"",VLOOKUP(C38,'[2]CENTRO DE CUSTO'!$A$3:$C$536,3,0)*G38/$K$10/60,"") | K38: =IF(C38<>"",VLOOKUP(C38,'CENTRO DE CUSTO'!$A$3:$C$536,3,0)*H38/60*I38,"") | L38: =I38*H38 -> 0
A39: 90 | E39: =IF(D39="","",VLOOKUP(D39,'[2]GRUPO MÁQUINA 2025'!A10:B407,2,0)) | J39: =IF(C39<>"",VLOOKUP(C39,'[2]CENTRO DE CUSTO'!$A$3:$C$536,3,0)*G39/$K$10/60,"") | K39: =IF(C39<>"",VLOOKUP(C39,'CENTRO DE CUSTO'!$A$3:$C$536,3,0)*H39/60*I39,"") | L39: =I39*H39 -> 0
A40: 100 | E40: =IF(D40="","",VLOOKUP(D40,'[2]GRUPO MÁQUINA 2025'!A11:B408,2,0)) | J40: =IF(C40<>"",VLOOKUP(C40,'[2]CENTRO DE CUSTO'!$A$3:$C$536,3,0)*G40/$K$10/60,"") | K40: =IF(C40<>"",VLOOKUP(C40,'CENTRO DE CUSTO'!$A$3:$C$536,3,0)*H40/60*I40,"") | L40: =I40*H40 -> 0
A41: 110 | E41: =IF(D41="","",VLOOKUP(D41,'[2]GRUPO MÁQUINA 2025'!A12:B409,2,0)) | J41: =IF(C41<>"",VLOOKUP(C41,'[2]CENTRO DE CUSTO'!$A$3:$C$536,3,0)*G41/$K$10/60,"") | K41: =IF(C41<>"",VLOOKUP(C41,'CENTRO DE CUSTO'!$A$3:$C$536,3,0)*H41/60*I41,"") | L41: =I41*H41 -> 0
A42: 120 | E42: =IF(D42="","",VLOOKUP(D42,'[2]GRUPO MÁQUINA 2025'!A13:B410,2,0)) | J42: =IF(C42<>"",VLOOKUP(C42,'[2]CENTRO DE CUSTO'!$A$3:$C$536,3,0)*G42/$K$10/60,"") | K42: =IF(C42<>"",VLOOKUP(C42,'CENTRO DE CUSTO'!$A$3:$C$536,3,0)*H42/60*I42,"") | L42: =I42*H42 -> 0
A43: 130 | B43: MOLDAR PEÇA | C43: 368 | D43: 343A | E43: =IF(D43="","",VLOOKUP(D43,'[2]GRUPO MÁQUINA 2025'!A14:B411,2,0)) -> MÁQ. TERMO FORMAGEM (A) MARCOPOLO | I43: 1 | J43: =IF(C43<>"",VLOOKUP(C43,'[2]CENTRO DE CUSTO'!$A$3:$C$536,3,0)*G43/$K$10/60,"") -> 0 | K43: =IF(C43<>"",VLOOKUP(C43,'CENTRO DE CUSTO'!$A$3:$C$536,3,0)*H43/60*I43,"") -> 0 | L43: =I43*H43 -> 0
A44: 140 | E44: =IF(D44="","",VLOOKUP(D44,'[2]GRUPO MÁQUINA 2025'!A15:B412,2,0)) | J44: =IF(C44<>"",VLOOKUP(C44,'[2]CENTRO DE CUSTO'!$A$3:$C$536,3,0)*G44/$K$10/60,"") | K44: =IF(C44<>"",VLOOKUP(C44,'CENTRO DE CUSTO'!$A$3:$C$536,3,0)*H44/60*I44,"") | L44: =I44*H44 -> 0
A45: 150 | E45: =IF(D45="","",VLOOKUP(D45,'[2]GRUPO MÁQUINA 2025'!A16:B413,2,0)) | J45: =IF(C45<>"",VLOOKUP(C45,'[2]CENTRO DE CUSTO'!$A$3:$C$536,3,0)*G45/$K$10/60,"") | K45: =IF(C45<>"",VLOOKUP(C45,'CENTRO DE CUSTO'!$A$3:$C$536,3,0)*H45/60*I45,"") | L45: =I45*H45 -> 0
A46: SOMATÓRIO DOS VALORES REFERENTES A MÃO-DE-OBRA.............................................. | J46: =SUM(J31:J45) -> 0.00100625 | K46: =SUM(K31:K45) -> 19.689775
A48: CUSTO DA PEÇA........ | K48: =K18+K26+K46+J46 -> 19.690781
A50: ESTRUTURA DO FERRAMENTAL / GABARITO / RACK
...

Sheet ORÇAMENTO PINTURA
A1: Código Amalcaburio | B1: Código Marcopolo | C1: Comprimento (mm) | D1: Largura (mm) | E1: Área (mm²) | F1: Área (m2) | G1: Tinta por mm ² | H1: Quantidade de tinta (mL) | I1: Catalizador (L) | J1: Tempo pintura (mm² por min) | K1: Tempo Pintura | L1: Cor | M1: Custo pintura PARA UM LADO DA PEÇA | O1: Custo pintura PARA DOIS LADO DA PEÇA | P1: Código Amalcaburio
A2: 802914000 | B2: 11276419 | C2: 571 | D2: 406 | E2: =PRODUCT(C2:D2) -> 231826 | G2: 3.26e-07 | H2: =E2*G2*1.89 -> 0.14283727 | I2: =H2/8 -> 0.017854659 | J2: 1.8181e-05 | K2: =E2*J2 -> 4.2148285 | L2: PRETO FOSCO | O2: 105479000 | P2: PRETO FOSCO
A3: 803402000 | B3: 11107694 | C3: 495 | D3: 395 | E3: =PRODUCT(C3:D3) -> 195525 | G3: 3.26e-07 | H3: =E3*G3*1.89 -> 0.12047077 | I3: =H3/8 -> 0.015058847 | J3: 1.8181e-05 | K3: =E3*J3 -> 3.55484 | L3: PRETO FOSCO
A4: 803406000 | B4: 10870475 | C4: 525 | D4: 361 | E4: =PRODUCT(C4:D4) -> 189525 | G4: 3.26e-07 | H4: =E4*G4*1.89 -> 0.11677393 | I4: =H4/8 -> 0.014596742 | J4: 1.8181e-05 | K4: =E4*J4 -> 3.445754 | L4: PRETO FOSCO
A5: 803455000 | B5: 10920424 | C5: 470 | D5: 360 | E5: =PRODUCT(C5:D5) -> 169200 | G5: 3.26e-07 | H5: =E5*G5 -> 0.0551592 | I5: =H5/8 -> 0.0068949 | J5: 1.8181e-05 | K5: =E5*J5 -> 3.0762252 | L5: PRETO FOSCO
A6: 803458000 | B6: 10738417 | C6: 569 | D6: 400 | E6: =PRODUCT(C6:D6) -> 227600 | G6: 3.26e-07 | H6: =E6*G6*1.89 -> 0.14023346 | I6: =H6/8 -> 0.017529183 | J6: 1.8181e-05 | K6: =E6*J6 -> 4.1379956 | L6: PRETO FOSCO
A7: 803465000 | B7: 10961664 | C7: 394 | D7: 349 | E7: =PRODUCT(C7:D7) -> 137506 | G7: 3.26e-07 | H7: =E7*G7 -> 0.044826956 | I7: =H7/8 -> 0.0056033695 | J7: 1.8181e-05 | K7: =E7*J7 -> 2.4999966 | L7: PRETO FOSCO
A8: 803473000 | B8: 10780075 | C8: 491 | D8: 380 | E8: =PRODUCT(C8:D8) -> 186580 | G8: 3.26e-07 | H8: =E8*G8*1.89 -> 0.1149594 | I8: =H8/8 -> 0.014369925 | J8: 1.8181e-05 | K8: =E8*J8 -> 3.392211 | L8: PRETO FOSCO
A9: 803474000 | B9: 11030580 | C9: 570 | D9: 354 | E9: =PRODUCT(C9:D9) -> 201780 | G9: 3.26e-07 | H9: =E9*G9*1.89 -> 0.12432473 | I9: =H9/8 -> 0.015540591 | J9: 1.8181e-05 | K9: =E9*J9 -> 3.6685622 | L9: PRETO FOSCO
A10: 803484000 | B10: 10998537 | C10: 464 | D10: 354 | E10: =PRODUCT(C10:D10) -> 164256 | G10: 3.26e-07 | H10: =E10*G10*1.89 -> 0.10120469 | I10: =H10/8 -> 0.012650586 | J10: 1.8181e-05 | K10: =E10*J10 -> 2.9863383 | L10: PRETO FOSCO
A11: 803504000 | B11: 11116985 | C11: 504 | D11: 353 | E11: =PRODUCT(C11:D11) -> 177912 | G11: 3.26e-07 | H11: =E11*G11*1.89 -> 0.1096187 | I11: =H11/8 -> 0.013702337 | J11: 1.8181e-05 | K11: =E11*J11 -> 3.2346181 | L11: PRETO FOSCO
A12: 803510000 | B12: 10993938 | C12: 555 | D12: 350 | E12: =PRODUCT(C12:D12) -> 194250 | G12: 3.26e-07 | H12: =E12*G12*1.89 -> 0.11968519 | I12: =H12/8 -> 0.014960649 | J12: 1.8181e-05 | K12: =E12*J12 -> 3.5316593 | L12: PRETO FOSCO
A13: 803535000 | B13: 11116987 | C13: 502 | D13: 238 | E13: =PRODUCT(C13:D13) -> 119476 | G13: 3.26e-07 | H13: =E13*G13*1.89 -> 0.073613943 | I13: =H13/8 -> 0.0092017428 | J13: 1.8181e-05 | K13: =E13*J13 -> 2.1721932 | L13: PRETO FOSCO
A14: 803537000 | B14: 10916599 | C14: 426 | D14: 355 | E14: =PRODUCT(C14:D14) -> 151230 | G14: 3.26e-07 | H14: =E14*G14*1.89 -> 0.093178852 | I14: =H14/8 -> 0.011647357 | J14: 1.8181e-05 | K14: =E14*J14 -> 2.7495126 | L14: PRETO FOSCO
A15: 803585000 | B15: 10373754 | C15: 511 | D15: 385 | E15: =PRODUCT(C15:D15) -> 196735 | G15: 3.26e-07 | H15: =E15*G15*1.89 -> 0.1212163 | I15: =H15/8 -> 0.015152038 | J15: 1.8181e-05 | K15: =E15*J15 -> 3.576839 | L15: PRETO FOSCO
A16: 803591000 | B16: 10993939 | C16: 500 | D16: 363 | E16: =PRODUCT(C16:D16) -> 181500 | G16: 3.26e-07 | H16: =E16*G16*1.89 -> 0.11182941 | I16: =H16/8 -> 0.013978676 | J16: 1.8181e-05 | K16: =E16*J16 -> 3.2998515 | L16: PRETO FOSCO
A17: 803642000 | B17: 10943061 | C17: 491 | D17: 352 | E17: =PRODUCT(C17:D17) -> 172832 | G17: 3.26e-07 | H17: =E17*G17*1.89 -> 0.10648871 | I17: =H17/8 -> 0.013311089 | J17: 1.8181e-05 | K17: =E17*J17 -> 3.1422586 | L17: PRETO FOSCO
A18: 803647000 | B18: 11196630 | C18: 543 | D18: 370 | E18: =PRODUCT(C18:D18) -> 200910 | G18: 3.26e-07 | H18: =E18*G18*1.89 -> 0.12378869 | I18: =H18/8 -> 0.015473586 | J18: 1.8181e-05 | K18: =E18*J18 -> 3.6527447 | L18: PRETO FOSCO
A19: 803683000 | B19: 10651364 | C19: 325 | D19: 230 | E19: =PRODUCT(C19:D19) -> 74750 | G19: 3.26e-07 | H19: =E19*G19*1.89 -> 0.046056465 | I19: =H19/8 -> 0.0057570581 | J19: 1.8181e-05 | K19: =E19*J19 -> 1.3590298 | L19: PRETO FOSCO
... A21: 803736000 | B21: 10419797 | C21: 85 | D21: 85 | E21: =PRODUCT(C21:D21) -> 7225 | G21: 3.26e-07 | H21: =E21*G21*1.89 -> 0.0044516115 | I21: =H21/8 -> 0.00055645144 | J21: 1.8181e-05 | K21: =E21*J21 -> 0.13135773 | L21: CINZA TITÂNIO
B22: 10227064 | C22: 520 | D22: 372 | E22: =PRODUCT(C22:D22) -> 193440 | G22: 3.26e-07 | H22: =E22*G22*1.89 -> 0.11918612 | I22: =H22/8 -> 0.014898265 | J22: 1.8181e-05 | K22: =E22*J22 -> 3.5169326 | L22: PRETO FOSCO
A23: 803924000 | B23: 10454751 | C23: 404 | D23: 397 | E23: =PRODUCT(C23:D23) -> 160388 | G23: 3.26e-07 | H23: =E23*G23*1.89 -> 0.098821462 | I23: =H23/8 -> 0.012352683 | J23: 1.8181e-05 | K23: =E23*J23 -> 2.9160142 | L23: PRETO FOSCO
A24: 803761000 | B24: 10451899 | C24: 669 | D24: 454 | E24: =PRODUCT(C24:D24) -> 303726 | G24: 3.26e-07 | H24: =E24*G24*1.89 -> 0.18713774 | I24: =H24/8 -> 0.023392217 | J24: 1.8181e-05 | K24: =E24*J24 -> 5.5220424 | L24: PRETO FOSCO
B25: 10554264 | C25: 375 | D25: 337 | E25: =PRODUCT(C25:D25) -> 126375 | G25: 3.26e-07 | H25: =E25*G25*1.89 -> 0.077864692 | I25: =H25/8 -> 0.0097330866 | J25: 1.8181e-05 | K25: =E25*J25 -> 2.2976239 | L25: PRETO FOSCO
A26: 803781000 | B26: 10657376 | C26: 550 | D26: 288 | E26: =PRODUCT(C26:D26) -> 158400 | G26: 3.26e-07 | H26: =E26*G26*1.89 -> 0.097596576 | I26: =H26/8 -> 0.012199572 | J26: 1.8181e-05 | K26: =E26*J26 -> 2.8798704 | L26: PRETO FOSCO
B27: 10745341 | C27: 469 | D27: 400 | E27: =PRODUCT(C27:D27) -> 187600 | G27: 3.26e-07 | H27: =E27*G27*1.89 -> 0.11558786 | I27: =H27/8 -> 0.014448483 | J27: 1.8181e-05 | K27: =E27*J27 -> 3.4107556 | L27: PRETO FOSCO
A28: 803840000 | B28: 11031883 | C28: 564 | D28: 440 | E28: =PRODUCT(C28:D28) -> 248160 | G28: 3.26e-07 | H28: =E28*G28*1.89 -> 0.1529013 | I28: =H28/8 -> 0.019112663 | J28: 1.8181e-05 | K28: =E28*J28 -> 4.511797 | L28: PRETO FOSCO
B29: 11143262 | C29: 465 | D29: 340 | E29: =PRODUCT(C29:D29) -> 158100 | G29: 3.26e-07 | H29: =E29*G29*1.89 -> 0.097411734 | I29: =H29/8 -> 0.012176467 | J29: 1.8181e-05 | K29: =E29*J29 -> 2.8744161 | L29: PRETO FOSCO
B30: 11202216 | C30: 544 | D30: 368 | E30: =PRODUCT(C30:D30) -> 200192 | G30: 3.26e-07 | H30: =E30*G30*1.89 -> 0.1233463 | I30: =H30/8 -> 0.015418287 | J30: 1.8181e-05 | K30: =E30*J30 -> 3.6396908 | L30: PRETO FOSCO
B31: 11254144 | C31: 487 | D31: 270 | E31: =PRODUCT(C31:D31) -> 131490 | G31: 3.26e-07 | H31: =E31*G31*1.89 -> 0.081016249 | I31: =H31/8 -> 0.010127031 | J31: 1.8181e-05 | K31: =E31*J31 -> 2.3906197 | L31: PRETO FOSCO
B32: 11145112 | C32: 610 | D32: 80 | E32: =PRODUCT(C32:D32) -> 48800 | G32: 3.26e-07 | H32: =E32*G32*1.5 -> 0.0238632 | I32: =H32/8 -> 0.0029829 | J32: 1.8181e-05 | K32: =E32*J32 -> 0.8872328 | L32: PRETO BRILHO
B33: 11145113 | C33: - | D33: - | E33: 52363 | G33: 3.26e-07 | H33: =E33*G33*1.5 -> 0.025605507 | I33: =H33/8 -> 0.0032006884 | J33: 1.8181e-05 | K33: =E33*J33 -> 0.9520117 | L33: PRETO BRILHO
B34: 11269282 | C34: - | D34: - | E34: 52363 | G34: 3.26e-07 | H34: =E34*G34*1.5 -> 0.025605507 | I34: =H34/8 -> 0.0032006884 | J34: 1.8181e-05 | K34: =E34*J34 -> 0.9520117 | L34: PRETO BRILHO
B35: 11270480 | C35: 610 | D35: 80 | E35: =PRODUCT(C35:D35) -> 48800 | G35: 3.26e-07 | H35: =E35*G35*1.5 -> 0.0238632 | I35: =H35/8 -> 0.0029829 | J35: 1.8181e-05 | K35: =E35*J35 -> 0.8872328 | L35: PRETO BRILHO
B36: 11272315 | C36: - | D36: - | E36: 24566 | G36: 3.26e-07 | H36: =E36*G36*1.5 -> 0.012012774 | I36: =H36/8 -> 0.0015015968 | J36: 1.8181e-05 | K36: =E36*J36 -> 0.44663445 | L36: PRETO BRILHO
B37: 11274397 | C37: - | D37: - | E37: 46373 | G37: 3.26e-07 | H37: =E37*G37*1.5 -> 0.022676397 | I37: =H37/8 -> 0.0028345496 | J37: 1.8181e-05 | K37: =E37*J37 -> 0.84310751 | L37: PRETO BRILHO
B38: 11274398 | C38: - | D38: - | E38: 46373 | G38: 3.26e-07 | H38: =E38*G38*1.5 -> 0.022676397 | I38: =H38/8 -> 0.0028345496 | J38: 1.8181e-05 | K38: =E38*J38 -> 0.84310751 | L38: PRETO BRILHO
B39: 17284870 | C39: 310 | D39: 125 | E39: =PRODUCT(C39:D39) -> 38750 | G39: 3.26e-07 | H39: =E39*G39*1.89 -> 0.023875425 | I39: =H39/8 -> 0.0029844281 | J39: 1.8181e-05 | K39: =E39*J39 -> 0.70451375 | L39: FUNDO CINZA
A40: 803764000 | B40: 11130013 | C40: 627 | D40: 570 | E40: =PRODUCT(C40:D40) -> 357390 | G40: 3.26e-07 | H40: =E40*G40 -> 0.11650914 | I40: =H40/8 -> 0.014563642 | J40: 1.8181e-05 | K40: =E40*J40 -> 6.4977076 | L40: PRETO FOSCO
A41: 803845000 | B41: 11390746 | C41: 512 | D41: 400 | E41: =PRODUCT(C41:D41) -> 204800 | G41: 3.26e-07 | H41: =E41*G41 -> 0.0667648 | I41: =H41/8 -> 0.0083456 | J41: 1.8181e-05 | K41: =E41*J41 -> 3.7234688 | L41: PRETO FOSCO
...

Sheet CENTRO DE CUSTO
A1: VALOR HORA POR CENTRO DE CUSTO
A2: C.C. | B2: DESCRIÇÃO | C2: CUSTO
A3: 312 | B3: MANUTENÇÃO | C3: 80
A4: 322 | B4: MODELARIA | C4: 80
A5: 323 | B5: PINTURA DE PEÇAS - TUNEL | C5: 1400
A6: 325 | B6: FERRAMENTARIA | C6: 80
A7: 338 | B7: PREPARAÇÃO PINTURA CABINE | C7: 188
A8: 339 | B8: ACABAMENTO TERMO FORMAGEM | C8: 105
A9: 343 | B9: TERMO FORMAGEM | C9: 230
A10: 345 | B10: PINTURA PÓ | C10: 170
A11: 348 | B11: CORTE LASER 3D | C11: 340
A12: 358 | B12: P&D | C12: 80
A13: 359 | B13: CORTE E DOBRA | C13: 140
A14: 360 | B14: PRENSAS | C14: 240
... A19: 370 | B19: CORTE LASER 2D | C19: 180

Sheet GRUPO MÁQUINA 2025
A1: Grp Maq | B1: Descrição
A2: 300-001 | B2: ACABAMENTO - ESTILETE
A3: 300-001 | B3: ACABAMENTO - EMBALAR
A4: 300-001 | B4: ACABAMENTO - DIVERSOS
A5: 300-001 | B5: ACABAMENTO - ESTILETE
A6: 301-001 | B6: BANCADA 13 - GUILHOTINA
A7: 301-002 | B7: GUILHOTINA MECANICA NEWTON
A8: 301-003 | B8: GUILHOTINA MECANICA
A9: 301-004 | B9: GUILHOTINA HIDR. GASPARIN
A10: 301-005 | B10: GUILHOTINA NEWTON GHNL
A11: 301-006 | B11: GUILHOTINA NEWTON GMN 2005
A12: 301A | B12: MAQ. SOLDA OXIACETILENO
... A383: 364-002 | B383: ACABAMENTO PU
A384: 367-001 | B384: 3101
A385: 367-002 | B385: TANQUE ESTANQUIEDADE 1 e 2
A386: 367-003 | B386: MAQUINA SOLDA OXIGENIO
A387: 367-004 | B387: BANCADA DE AJUSTE ABERTURA
A388: 367-005 | B388: BANCADA DE AJUSTE PLANICIDADE
A389: 367-007 | B389: GABARITO MONTAGEM ASSOALHO MAN
A390: 367-008 | B390: GABARITO MONTAGEM PAINEL TRAS. MAN
A391: 367-009 | B391: GABARITO MONTAGEM LAT. TRAVES MAN
A392: 367-010 | B392: GABARITO MONTAGEM TETO E FRONTAL MAN
A393: 367-011 | B393: GABARITO MONTAGEM PORTAS MAN
A394: 367-012 | B394: GABARITO MONTAGEM BACIÃO E FECHAM. MAN
A395: 367-013 | B395: MAQ. SOLDA PORCAS QUADRADAS MAN
A396: 367-014 | B396: MAQ. SOLDA PORCAS SEXTAVADA MAN
... A400: TRN2 | B400: TREINAMENTO 2
